<sdf version='1.8'>
  <world name='arm_robot_world'>
    <scene>
      <ambient>1 1 1 1</ambient>
      <background>0.8 0.8 0.8 1</background>
      <shadows>1</shadows>
    </scene>
    <light name='sun' type='directional'>
      <cast_shadows>1</cast_shadows>
      <pose>0 0 10 0 0 0</pose>
      <diffuse>0.8 0.8 0.8 1</diffuse>
      <specular>0.2 0.2 0.2 1</specular>
      <attenuation>
        <range>1000</range>
        <constant>0.90000000000000002</constant>
        <linear>0.01</linear>
        <quadratic>0.001</quadratic>
      </attenuation>
      <direction>-0.5 0.1 -0.9</direction>
      <spot>
        <inner_angle>0</inner_angle>
        <outer_angle>0</outer_angle>
        <falloff>0</falloff>
      </spot>
    </light>
    <gravity>0 0 -9.8</gravity>
    <magnetic_field>6e-06 2.3e-05 -4.2e-05</magnetic_field>
    <atmosphere type='adiabatic'/>
    <physics type='ode'>
      <max_step_size>0.001</max_step_size>
      <real_time_factor>1</real_time_factor>
      <real_time_update_rate>1000</real_time_update_rate>
    </physics>
   
    <plugin filename="libignition-gazebo-physics-system.so" name="ignition::gazebo::systems::Physics">
    </plugin>

    <plugin
            filename="libignition-gazebo-user-commands-system.so"
            name="ignition::gazebo::systems::UserCommands">
    </plugin>

    <plugin
            filename="libignition-gazebo-scene-broadcaster-system.so"
            name="ignition::gazebo::systems::SceneBroadcaster">
    </plugin>


    <model name='ur5_rg2'>
      <joint name='ur5_rg2_joint_world' type='fixed'>
        <parent>world</parent>
        <child>base_link</child>
      </joint>
      <link name='base_link'>
        <visual name='base_link_visual'>
          <geometry>
            <mesh>
              <uri>meshes/visual/ur5/base.dae</uri>
            </mesh>
          </geometry>
          <plugin name='__default__' filename='__default__'/>
        </visual>
        <collision name='base_link_collision'>
          <geometry>
            <mesh>
              <uri>meshes/collision/ur5/base.stl</uri>
            </mesh>
          </geometry>
          <surface>
            <friction>
              <ode>
                <mu>1.2</mu>
                <mu2>1.2</mu2>
              </ode>
            </friction>
          </surface>
        </collision>
        <inertial>
          <pose>-1e-06 0.004422 0.184343 0 -0 0</pose>
          <mass>4.2103896941738119</mass>
          <inertia>
            <ixx>0.093096705606025731</ixx>
            <iyy>0.092570376512874919</iyy>
            <izz>0.0043106456139852993</izz>
            <ixy>5.7112708727596737e-09</ixy>
            <ixz>2.0039833861772347e-07</ixz>
            <iyz>0.0047053532779924665</iyz>
          </inertia>
        </inertial>
      </link>
      <link name='shoulder_link'>
        <pose relative_to='shoulder_pan_joint'>0 0 0 0 -0 0</pose>
        <visual name='shoulder_link_visual'>
          <geometry>
            <mesh>
              <uri>meshes/visual/ur5/shoulder.dae</uri>
            </mesh>
          </geometry>
          <plugin name='__default__' filename='__default__'/>
        </visual>
        <collision name='shoulder_link_collision'>
          <geometry>
            <mesh>
              <uri>meshes/collision/ur5/shoulder.stl</uri>
            </mesh>
          </geometry>
          <surface>
            <friction>
              <ode>
                <mu>1.2</mu>
                <mu2>1.2</mu2>
              </ode>
            </friction>
          </surface>
        </collision>
        <inertial>
          <pose>-4e-06 0.009273 -0.001856 0 -0 0</pose>
          <mass>2.6078628081050645</mass>
          <inertia>
            <ixx>0.0061589073947738698</ixx>
            <iyy>0.0055629329831981891</iyy>
            <izz>0.0052550824704143189</izz>
            <ixy>8.4866787164370867e-07</ixy>
            <ixz>1.436028981488676e-07</ixz>
            <iyz>-0.00018809980689883695</iyz>
          </inertia>
        </inertial>
      </link>
      <link name='upper_arm_link'>
        <pose relative_to='shoulder_lift_joint'>0 0 0 0 -0 0</pose>
        <visual name='upper_arm_link_visual'>
          <geometry>
            <mesh>
              <uri>meshes/visual/ur5/upperarm.dae</uri>
            </mesh>
          </geometry>
          <plugin name='__default__' filename='__default__'/>
        </visual>
        <collision name='upper_arm_link_collision'>
          <geometry>
            <mesh>
              <uri>meshes/collision/ur5/upperarm.stl</uri>
            </mesh>
          </geometry>
          <surface>
            <friction>
              <ode>
                <mu>1.2</mu>
                <mu2>1.2</mu2>
              </ode>
            </friction>
          </surface>
        </collision>
        <inertial>
          <pose>0 -0.001072 0.2125 0 -0 0</pose>
          <mass>9.0345562029460567</mass>
          <inertia>
            <ixx>0.25665374542481989</ixx>
            <iyy>0.25483850258961777</iyy>
            <izz>0.016022276702360172</izz>
            <ixy>-2.2173460061911962e-09</ixy>
            <ixz>2.3397723734924104e-06</ixz>
            <iyz>5.7018971497364493e-09</iyz>
          </inertia>
        </inertial>
      </link>
      <link name='forearm_link'>
        <pose relative_to='elbow_joint'>0 0 0 0 -0 0</pose>
        <visual name='forearm_link_visual'>
          <geometry>
            <mesh>
              <uri>meshes/visual/ur5/forearm.dae</uri>
            </mesh>
          </geometry>
          <plugin name='__default__' filename='__default__'/>
        </visual>
        <collision name='forearm_link_collision'>
          <geometry>
            <mesh>
              <uri>meshes/collision/ur5/forearm.stl</uri>
            </mesh>
          </geometry>
          <surface>
            <friction>
              <ode>
                <mu>1.2</mu>
                <mu2>1.2</mu2>
              </ode>
            </friction>
          </surface>
        </collision>
        <inertial>
          <pose>-1e-06 0.004422 0.184343 0 -0 0</pose>
          <mass>4.2103896941738119</mass>
          <inertia>
            <ixx>0.093096705606025731</ixx>
            <iyy>0.092570376512874919</iyy>
            <izz>0.0043106456139852993</izz>
            <ixy>5.7112708727596737e-09</ixy>
            <ixz>2.0039833861772347e-07</ixz>
            <iyz>0.0047053532779924665</iyz>
          </inertia>
        </inertial>
      </link>
      <link name='wrist_1_link'>
        <pose relative_to='wrist_1_joint'>0 0 0 0 -0 0</pose>
        <visual name='wrist_1_link_visual'>
          <geometry>
            <mesh>
              <uri>meshes/visual/ur5/wrist1.dae</uri>
            </mesh>
          </geometry>
          <plugin name='__default__' filename='__default__'/>
        </visual>
        <collision name='wrist_1_link_collision'>
          <geometry>
            <mesh>
              <uri>meshes/collision/ur5/wrist1.stl</uri>
            </mesh>
          </geometry>
          <surface>
            <friction>
              <ode>
                <mu>1.2</mu>
                <mu2>1.2</mu2>
              </ode>
            </friction>
          </surface>
        </collision>
        <inertial>
          <pose>2e-06 0.088624 -0.003577 0 -0 0</pose>
          <mass>0.86527830445974219</mass>
          <inertia>
            <ixx>0.0011006744464830784</ixx>
            <iyy>0.0010246557119841899</iyy>
            <izz>0.00071252139848030683</izz>
            <ixy>-4.062057055066431e-08</ixy>
            <ixz>-2.4411330817463469e-08</ixz>
            <iyz>1.000924524333879e-05</iyz>
          </inertia>
        </inertial>
      </link>
      <link name='wrist_2_link'>
        <pose relative_to='wrist_2_joint'>0 0 0 0 -0 0</pose>
        <visual name='wrist_2_link_visual'>
          <geometry>
            <mesh>
              <uri>meshes/visual/ur5/wrist2.dae</uri>
            </mesh>
          </geometry>
          <plugin name='__default__' filename='__default__'/>
        </visual>
        <collision name='wrist_2_link_collision'>
          <geometry>
            <mesh>
              <uri>meshes/collision/ur5/wrist2.stl</uri>
            </mesh>
          </geometry>
          <surface>
            <friction>
              <ode>
                <mu>1.2</mu>
                <mu2>1.2</mu2>
              </ode>
            </friction>
          </surface>
        </collision>
        <inertial>
          <pose>-2e-06 -0.003577 0.090105 0 -0 0</pose>
          <mass>0.86527868669555918</mass>
          <inertia>
            <ixx>0.0010980920821000012</ixx>
            <iyy>0.0007099378137563144</iyy>
            <izz>0.0010246570857519936</izz>
            <ixy>2.4360325066595751e-08</ixy>
            <ixz>4.0470860506011448e-08</ixz>
            <iyz>4.9608519490841403e-06</iyz>
          </inertia>
        </inertial>
      </link>
      <link name='wrist_3_link'>
        <pose relative_to='wrist_3_joint'>0 0 0 0 -0 0</pose>
        <visual name='wrist_3_link_visual'>
          <geometry>
            <mesh>
              <uri>meshes/visual/ur5/wrist3.dae</uri>
            </mesh>
          </geometry>
          <plugin name='__default__' filename='__default__'/>
        </visual>
        <collision name='wrist_3_link_collision'>
          <geometry>
            <mesh>
              <uri>meshes/collision/ur5/wrist3.stl</uri>
            </mesh>
          </geometry>
          <surface>
            <friction>
              <ode>
                <mu>1.2</mu>
                <mu2>1.2</mu2>
              </ode>
            </friction>
          </surface>
        </collision>
        <inertial>
          <pose>0 0.063091 0.00019 0 -0 0</pose>
          <mass>0.23285976783205536</mass>
          <inertia>
            <ixx>0.00010068520800989181</ixx>
            <iyy>0.00016016377462915846</iyy>
            <izz>9.9511992887582458e-05</izz>
            <ixy>-1.3195380569038253e-11</ixy>
            <ixz>2.0466677535340047e-11</ixz>
            <iyz>3.4214542033621641e-08</iyz>
          </inertia>
        </inertial>
      </link>
      <joint name='shoulder_pan_joint' type='revolute'>
        <pose relative_to='base_link'>0 0 0.089159 0 -0 0</pose>
        <parent>base_link</parent>
        <child>shoulder_link</child>
        <axis>
          <xyz>0 0 1</xyz>
          <limit>
            <effort>150</effort>
            <lower>-6.2831900000000003</lower>
            <upper>6.2831900000000003</upper>
            <velocity>3.1499999999999999</velocity>
          </limit>
          <dynamics>
            <spring_reference>0</spring_reference>
            <spring_stiffness>0</spring_stiffness>
            <damping>30</damping>
            <friction>4</friction>
          </dynamics>
        </axis>
      </joint>
      <joint name='shoulder_lift_joint' type='revolute'>
        <pose relative_to='shoulder_link'>0 0.13585 0 0 -0 0</pose>
        <parent>shoulder_link</parent>
        <child>upper_arm_link</child>
        <axis>
          <xyz>0 1 0</xyz>
          <limit>
            <effort>150</effort>
            <lower>-1.2831900000000003</lower>
            <upper>1.2831900000000003</upper>
            <velocity>1.1499999999999999</velocity>
          </limit>
          <dynamics>
            <spring_reference>0</spring_reference>
            <spring_stiffness>0</spring_stiffness>
            <damping>45</damping>
            <friction>6</friction>
          </dynamics>
        </axis>
      </joint>
      <joint name='elbow_joint' type='revolute'>
        <pose relative_to='upper_arm_link'>0 -0.1197 0.425 0 -0 0</pose>
        <parent>upper_arm_link</parent>
        <child>forearm_link</child>
        <axis>
          <xyz>0 1 0</xyz>
          <limit>
            <effort>150</effort>
            <lower>-6.2831900000000003</lower>
            <upper>6.2831900000000003</upper>
            <velocity>3.1499999999999999</velocity>
          </limit>
          <dynamics>
            <spring_reference>0</spring_reference>
            <spring_stiffness>0</spring_stiffness>
            <damping>35</damping>
            <friction>5</friction>
          </dynamics>
        </axis>
      </joint>
      <joint name='wrist_1_joint' type='revolute'>
        <pose relative_to='forearm_link'>0 0 0.39225 0 -0 0</pose>
        <parent>forearm_link</parent>
        <child>wrist_1_link</child>
        <axis>
          <xyz>0 1 0</xyz>
          <limit>
            <effort>28</effort>
            <lower>-6.2831900000000003</lower>
            <upper>6.2831900000000003</upper>
            <velocity>3.2000000000000002</velocity>
          </limit>
          <dynamics>
            <spring_reference>0</spring_reference>
            <spring_stiffness>0</spring_stiffness>
            <damping>25</damping>
            <friction>3.5</friction>
          </dynamics>
        </axis>
      </joint>
      <joint name='wrist_2_joint' type='revolute'>
        <pose relative_to='wrist_1_link'>0 0.093 0 0 -0 0</pose>
        <parent>wrist_1_link</parent>
        <child>wrist_2_link</child>
        <axis>
          <xyz>0 0 1</xyz>
          <limit>
            <effort>28</effort>
            <lower>-3.2831900000000003</lower>
            <upper>3.2831900000000003</upper>
            <velocity>3.2000000000000002</velocity>
          </limit>
          <dynamics>
            <spring_reference>0</spring_reference>
            <spring_stiffness>0</spring_stiffness>
            <damping>20</damping>
            <friction>2.5</friction>
          </dynamics>
        </axis>
      </joint>
      <joint name='wrist_3_joint' type='revolute'>
        <pose relative_to='wrist_2_link'>0 0 0.09465 0 -0 0</pose>
        <parent>wrist_2_link</parent>
        <child>wrist_3_link</child>
        <axis>
          <xyz>0 1 0</xyz>
          <limit>
            <effort>28</effort>
            <lower>-6.2831900000000003</lower>
            <upper>6.2831900000000003</upper>
            <velocity>3.2000000000000002</velocity>
          </limit>
          <dynamics>
            <spring_reference>0</spring_reference>
            <spring_stiffness>0</spring_stiffness>
            <damping>15</damping>
            <friction>1.75</friction>
          </dynamics>
        </axis>
      </joint>
      <joint name='ur5_hand_joint' type='fixed'>
        <pose relative_to='wrist_3_link'>0 0.0823 0 1.5708 -0 1.5708</pose>
        <parent>wrist_3_link</parent>
        <child>rg2_hand</child>
      </joint>
      <link name='rg2_hand'>
        <pose relative_to='ur5_hand_joint'>0 0 0 0 -0 0</pose>
        <visual name='rg2_hand_visual'>
          <pose>0 0 0 0 -0 0</pose>
          <geometry>
            <mesh>
              <uri>meshes/visual/rg2/hand.dae</uri>
            </mesh>
          </geometry>
          <plugin name='__default__' filename='__default__'/>
        </visual>
        <collision name='rg2_hand_collision'>
          <pose>0 0 0 0 -0 0</pose>
          <geometry>
            <mesh>
              <uri>meshes/collision/rg2/hand.stl</uri>
            </mesh>
          </geometry>
          <surface>
            <friction>
              <ode>
                <mu>1.2</mu>
                <mu2>1.2</mu2>
              </ode>
            </friction>
          </surface>
        </collision>
        <inertial>
          <pose>0.057581 -0.000169 -3.3e-05 0 -0 0</pose>
          <mass>0.29881464108881906</mass>
          <inertia>
            <ixx>0.00010934311942148434</ixx>
            <iyy>0.00033275681732290708</iyy>
            <izz>0.00037338963627732164</izz>
            <ixy>2.4297126288189813e-07</ixy>
            <ixz>5.3958894994201004e-08</ixz>
            <iyz>2.4899876853227836e-07</iyz>
          </inertia>
        </inertial>
      </link>
      <link name='rg2_leftfinger'>
        <pose relative_to='rg2_finger_joint1'>0 0 0 0 -0 0</pose>
        <visual name='rg2_leftfinger_visual'>
          <geometry>
            <mesh>
              <uri>meshes/visual/rg2/finger.dae</uri>
            </mesh>
          </geometry>
          <plugin name='__default__' filename='__default__'/>
        </visual>
        <collision name='rg2_leftfinger_collision'>
          <geometry>
            <mesh>
              <uri>meshes/collision/rg2/finger.stl</uri>
            </mesh>
          </geometry>
          <surface>
            <friction>
              <ode>
                <mu>2.1499999999999999</mu>
                <mu2>2.1499999999999999</mu2>
              </ode>
            </friction>
          </surface>
        </collision>
        <inertial>
          <pose>-0.017687 -0.008191 -4.2e-05 0 -0 0</pose>
          <mass>0.24059267945559043</mass>
          <inertia>
            <ixx>3.3970932890017096e-05</ixx>
            <iyy>0.00029230476124314346</iyy>
            <izz>0.00030917405435097734</izz>
            <ixy>-4.8854610840491595e-05</ixy>
            <ixz>-1.1765879805737544e-08</ixz>
            <iyz>1.6350676533062336e-08</iyz>
          </inertia>
        </inertial>
      </link>
      <link name='rg2_rightfinger'>
        <pose relative_to='rg2_finger_joint2'>0 0 0 0 -0 0</pose>
        <visual name='rg2_rightfinger_visual'>
          <pose>0 0 0 3.14159 -0 0</pose>
          <geometry>
            <mesh>
              <uri>meshes/visual/rg2/finger.dae</uri>
            </mesh>
          </geometry>
          <plugin name='__default__' filename='__default__'/>
        </visual>
        <collision name='rg2_rightfinger_collision'>
          <pose>0 0 0 3.14159 -0 0</pose>
          <geometry>
            <mesh>
              <uri>meshes/collision/rg2/finger.stl</uri>
            </mesh>
          </geometry>
          <surface>
            <friction>
              <ode>
                <mu>2.1499999999999999</mu>
                <mu2>2.1499999999999999</mu2>
              </ode>
            </friction>
          </surface>
        </collision>
        <inertial>
          <pose>-0.017687 -0.008191 -4.2e-05 3.14159 -0 0</pose>
          <mass>0.24059267945559043</mass>
          <inertia>
            <ixx>3.3970932890017096e-05</ixx>
            <iyy>0.00029230476124314346</iyy>
            <izz>0.00030917405435097734</izz>
            <ixy>-4.8854610840491595e-05</ixy>
            <ixz>-1.1765879805737544e-08</ixz>
            <iyz>1.6350676533062336e-08</iyz>
          </inertia>
        </inertial>
      </link>
      <joint name='rg2_finger_joint1' type='revolute'>
        <pose relative_to='rg2_hand'>0.105 0.017 0 0 -0 0</pose>
        <parent>rg2_hand</parent>
        <child>rg2_leftfinger</child>
        <axis>
          <xyz>0 0 1</xyz>
          <limit>
            <effort>10.6</effort>
            <lower>0</lower>
            <upper>1.1799999999999999</upper>
            <velocity>1.5700000000000001</velocity>
          </limit>
          <dynamics>
            <spring_reference>0</spring_reference>
            <spring_stiffness>0</spring_stiffness>
            <damping>1</damping>
            <friction>0.0050000000000000001</friction>
          </dynamics>
        </axis>
      </joint>
      <joint name='rg2_finger_joint2' type='revolute'>
        <pose relative_to='rg2_hand'>0.105 -0.017 0 0 -0 0</pose>
        <parent>rg2_hand</parent>
        <child>rg2_rightfinger</child>
        <axis>
          <xyz>0 0 -1</xyz>
          <limit>
            <effort>10.6</effort>
            <lower>0</lower>
            <upper>1.1799999999999999</upper>
            <velocity>1.5700000000000001</velocity>
          </limit>
          <dynamics>
            <spring_reference>0</spring_reference>
            <spring_stiffness>0</spring_stiffness>
            <damping>1</damping>
            <friction>0.0050000000000000001</friction>
          </dynamics>
        </axis>
      </joint>
      <link name='tool0'>
        <pose relative_to='end_effector_frame_fixed_joint'>0 0 0 0 -0 0</pose>
      </link>
      <joint name='end_effector_frame_fixed_joint' type='fixed'>
        <pose relative_to='wrist_3_link'>0 0.275 0 -1.5708 0 0</pose>
        <parent>wrist_3_link</parent>
        <child>tool0</child>
      </joint>
      <pose>0 0 0 0 0 0</pose>

      <!-- Joint Trajectory Controller -->

      <plugin filename="libignition-gazebo-joint-trajectory-controller-system.so" name="ignition::gazebo::systems::JointTrajectoryController">
        <topic>/model/ur5_rg2/arm_controller</topic>
        <joint_name>shoulder_pan_joint</joint_name>
        <initial_position>0</initial_position>
        <position_p_gain>3000</position_p_gain>
        <position_d_gain>15</position_d_gain>
        <position_i_gain>1650</position_i_gain>
        <position_i_min>-15</position_i_min>
        <position_i_max>15</position_i_max>
        <position_cmd_min>-150</position_cmd_min>
        <position_cmd_max>150</position_cmd_max>
        <!-- config of PID and limts for velocity -->
        <velocity_p_gain>0.06</velocity_p_gain>
        <velocity_i_gain>100</velocity_i_gain>
        <velocity_cmd_min>0</velocity_cmd_min>
        <velocity_cmd_max>3.14</velocity_cmd_max>

        <joint_name>shoulder_lift_joint</joint_name>
        <initial_position>0</initial_position>
        <position_p_gain>9500</position_p_gain>
        <position_d_gain>47.5</position_d_gain>
        <position_i_gain>5225</position_i_gain>
        <position_i_min>-47.5</position_i_min>
        <position_i_max>47.5</position_i_max>
        <position_cmd_min>-150</position_cmd_min>
        <position_cmd_max>150</position_cmd_max>
        <!-- config of PID and limts for velocity -->
        <velocity_p_gain>0.06</velocity_p_gain>
        <velocity_i_gain>100</velocity_i_gain>
        <velocity_cmd_min>0</velocity_cmd_min>
        <velocity_cmd_max>3.14</velocity_cmd_max>

        <joint_name>elbow_joint</joint_name>
        <initial_position>0</initial_position>
        <position_p_gain>6500</position_p_gain>
        <position_d_gain>32.5</position_d_gain>
        <position_i_gain>3575</position_i_gain>
        <position_i_min>-32.5</position_i_min>
        <position_i_max>32.5</position_i_max>
        <position_cmd_min>-150</position_cmd_min>
        <position_cmd_max>150</position_cmd_max>
        <!-- config of PID and limts for velocity -->
        <velocity_p_gain>0.06</velocity_p_gain>
        <velocity_i_gain>100</velocity_i_gain>
        <velocity_cmd_min>0</velocity_cmd_min>
        <velocity_cmd_max>3.14</velocity_cmd_max>

        <joint_name>wrist_1_joint</joint_name>
        <initial_position>0</initial_position>
        <position_p_gain>5000</position_p_gain>
        <position_d_gain>20</position_d_gain>
        <position_i_gain>1200</position_i_gain>
        <position_i_min>-30</position_i_min>
        <position_i_max>30</position_i_max>
        <position_cmd_min>-28</position_cmd_min>
        <position_cmd_max>28</position_cmd_max>
        <!-- config of PID and limts for velocity -->
        <velocity_p_gain>0.06</velocity_p_gain>
        <velocity_i_gain>100</velocity_i_gain>
        <velocity_cmd_min>0</velocity_cmd_min>
        <velocity_cmd_max>3.14</velocity_cmd_max>

        <joint_name>wrist_2_joint</joint_name>
        <initial_position>0</initial_position>
        <position_p_gain>4250</position_p_gain>
        <position_d_gain>10</position_d_gain>
        <position_i_gain>250</position_i_gain>
        <position_i_min>-6.88</position_i_min>
        <position_i_max>6.88</position_i_max>
        <position_cmd_min>-28</position_cmd_min>
        <position_cmd_max>28</position_cmd_max>
        <!-- config of PID and limts for velocity -->
        <velocity_p_gain>0.06</velocity_p_gain>
        <velocity_i_gain>100</velocity_i_gain>
        <velocity_cmd_min>0</velocity_cmd_min>
        <velocity_cmd_max>3.14</velocity_cmd_max>

        <!-- additional joints to be controlled-->
        <joint_name>wrist_3_joint</joint_name>
        <initial_position>0</initial_position>
        <position_p_gain>3000</position_p_gain>
        <position_d_gain>2.5</position_d_gain>
        <position_i_gain>775</position_i_gain>
        <position_i_min>-6.25</position_i_min>
        <position_i_max>6.25</position_i_max>
        <position_cmd_min>-28</position_cmd_min>
        <position_cmd_max>28</position_cmd_max>
        

    <!--     <joint_name>rg2_finger_joint1</joint_name>
        <initial_position>0</initial_position>
        <position_p_gain>150</position_p_gain>
        <position_d_gain>0.05</position_d_gain>
        <position_i_gain>50</position_i_gain>
        <position_i_min>-10</position_i_min>
        <position_i_max>10</position_i_max>
        <position_cmd_min>-10.6</position_cmd_min>
        <position_cmd_max>10.6</position_cmd_max>

        <joint_name>rg2_finger_joint2</joint_name>
        <initial_position>0</initial_position>
        <position_p_gain>150</position_p_gain>
        <position_d_gain>0.05</position_d_gain>
        <position_i_gain>50</position_i_gain>
        <position_i_min>-10</position_i_min>
        <position_i_max>10</position_i_max>
        <position_cmd_min>-10.6</position_cmd_min>
        <position_cmd_max>10.6</position_cmd_max> -->
      </plugin>

       <plugin filename="libignition-gazebo-joint-trajectory-controller-system.so" name="ignition::gazebo::systems::JointTrajectoryController">
        <topic>/model/ur5_rg2/gripper_controller</topic>
        <joint_name>rg2_finger_joint1</joint_name>
        <initial_position>0</initial_position>
        <position_p_gain>150</position_p_gain>
        <position_d_gain>0.05</position_d_gain>
        <position_i_gain>50</position_i_gain>
        <position_i_min>-10</position_i_min>
        <position_i_max>10</position_i_max>
        <position_cmd_min>-10.6</position_cmd_min>
        <position_cmd_max>10.6</position_cmd_max>

        <joint_name>rg2_finger_joint2</joint_name>
        <initial_position>0</initial_position>
        <position_p_gain>150</position_p_gain>
        <position_d_gain>0.05</position_d_gain>
        <position_i_gain>50</position_i_gain>
        <position_i_min>-10</position_i_min>
        <position_i_max>10</position_i_max>
        <position_cmd_min>-10.6</position_cmd_min>
        <position_cmd_max>10.6</position_cmd_max>
      </plugin>


      <plugin filename="libignition-gazebo-joint-state-publisher-system.so" name="ignition::gazebo::systems::JointStatePublisher">
        <joint_name>shoulder_pan_joint</joint_name>
        <joint_name>shoulder_lift_joint</joint_name>
        <joint_name>elbow_joint</joint_name>
        <joint_name>wrist_1_joint</joint_name>
        <joint_name>wrist_2_joint</joint_name>  
        <joint_name>wrist_3_joint</joint_name> 
        <joint_name>rg2_finger_joint1</joint_name> 
        <joint_name>rg2_finger_joint2</joint_name> 
      </plugin>

    </model>
  </world>
</sdf>
